handle() method used to recover from exceptions. It is called whether or not an exception occurs.




            package test;

            import java.util.concurrent.CompletableFuture;

            public class TestCF {
              public static void main(String[] args)throws Exception{
                Integer age = -1;

                CompletableFuture<String> maturityFuture = CompletableFuture.supplyAsync(() -> {
                    if(age < 0) {
                        throw new IllegalArgumentException("Age can not be negative");
                    }
                    if(age > 18) {
                        return "Adult";
                    } else {
                        return "Child";
                    }
                }).handle((res, ex) -> {
                    if(ex != null) {
                        System.out.println("Oops! We have an exception - " + ex.getMessage());
                        return "Unknown!";
                    }
                    return res;
                });

                System.out.println("Maturity : " + maturityFuture.get());
              }

            }
